<robot name="mini_bot" xmlns:xacro="http://www.ros.org/wiki/xacro">
  <link name="base_link">
    <visual>
      <origin xyz="0 0 -0.05"/>
      <geometry>
        <box size="0.30 0.30 0.20"/>
      </geometry>
      <material name="blue">
        <color rgba="0 0 1 1"/>
      </material>
    </visual>
     
    <collision>
      <origin xyz="0 0 -0.05"/>
      <geometry>
        <box size="0.30 0.30 0.10"/>
      </geometry>
    </collision>

    <inertial>
      <origin xyz="0 0 -0.05"/>
      <mass value="5.0"/>
      <inertia
        ixx="0.1" iyy="0.1" izz="0.1"
        ixy="0" ixz="0" iyz="0"/>
    </inertial>
          
  </link>

  <gazebo reference="base_link">
    <material>Gazebo/Blue</material>
  </gazebo>

  <xacro:macro name="wheel" params="name x y">

    <link name="${name}">
      <visual>
        <geometry>
          <cylinder radius="0.10" length="0.05"/>
        </geometry>
      </visual>

      <collision>
        <geometry>
          <cylinder radius="0.10" length="0.05"/>
        </geometry>
      </collision>

      <inertial>
        <mass value="0.5"/>
        <origin xyz="0 0 0"/>
        <inertia
          ixx="0.001" iyy="0.001" izz="0.001"
          ixy="0" ixz="0" iyz="0"/>
      </inertial>
    </link>

    <joint name="${name}_joint" type="continuous">
      <parent link="base_link"/>
      <child link="${name}"/>
      <origin xyz="${x} ${y} -0.15" rpy="0 1.5708 0"/>
      <axis xyz="0 1 0"/>
    </joint>

    <gazebo reference="${name}">
      <material>Gazebo/Black</material>
      <mu1>1.0</mu1>
      <mu2>1.0</mu2>
      <kp>100000.0</kp>
      <kd>10.0</kd>
    </gazebo>

  </xacro:macro>

  <xacro:wheel name="wheel_fl" x="0.15" y="0.15"/> 
  <xacro:wheel name="wheel_fr" x="0.15" y="-0.15"/> 
  <xacro:wheel name="wheel_rl" x="-0.15" y="0.15"/> 
  <xacro:wheel name="wheel_rr" x="-0.15" y="-0.15"/>

  <ros2_control name="MiniBotSystem" type="system">
    <hardware>
      <plugin>gazebo_ros2_control/GazeboSystem</plugin>
    </hardware>

    <joint name="wheel_fl_joint">
      <command_interface name="velocity"/>
      <state_interface name="position"/>
      <state_interface name="velocity"/>
    </joint>

    <joint name="wheel_fr_joint">
      <command_interface name="velocity"/>
      <state_interface name="position"/>
      <state_interface name="velocity"/>
    </joint>

    <joint name="wheel_rl_joint">
      <command_interface name="velocity"/>
      <state_interface name="position"/>
      <state_interface name="velocity"/>
    </joint>
    
    <joint name="wheel_rr_joint">
      <command_interface name="velocity"/>
      <state_interface name="position"/>
      <state_interface name="velocity"/>
    </joint>
  </ros2_control>

</robot>
